2025-02-16 20:27:14,267:DEBUG:certbot._internal.main:certbot version: 3.2.0
2025-02-16 20:27:14,267:DEBUG:certbot._internal.main:Location of certbot entry point: /usr/local/bin/certbot
2025-02-16 20:27:14,267:DEBUG:certbot._internal.main:Arguments: []
2025-02-16 20:27:14,267:DEBUG:certbot._internal.main:Discovered plugins: PluginsRegistry(PluginEntryPoint#manual,PluginEntryPoint#null,PluginEntryPoint#standalone,PluginEntryPoint#webroot)
2025-02-16 20:27:14,279:DEBUG:certbot._internal.log:Root logging level set at 30
2025-02-16 20:27:14,280:DEBUG:certbot._internal.display.obj:Notifying user: 
- - - - - - - - - - - - - - - - - - - - - - - - - - - - - - - - - - - - - - - -
2025-02-16 20:27:14,280:DEBUG:certbot._internal.display.obj:Notifying user: No renewals were attempted.
2025-02-16 20:27:14,280:DEBUG:certbot._internal.display.obj:Notifying user: - - - - - - - - - - - - - - - - - - - - - - - - - - - - - - - - - - - - - - - -
2025-02-16 20:27:14,280:DEBUG:certbot._internal.renewal:no renewal failures
2025-02-16 20:27:14,280:DEBUG:certbot.util:Exception occurred releasing lock: LockFile(/var/lib/letsencrypt/.certbot.lock) <released>
Traceback (most recent call last):
  File "/opt/certbot/src/certbot/certbot/util.py", line 241, in _release_locks
    dir_lock.release()
  File "/opt/certbot/src/certbot/certbot/_internal/lock.py", line 66, in release
    self._lock_mechanism.release()
  File "/opt/certbot/src/certbot/certbot/_internal/lock.py", line 172, in release
    os.remove(self._path)
FileNotFoundError: [Errno 2] No such file or directory: '/var/lib/letsencrypt/.certbot.lock'
